# 45장 프로미스

- 자바스크립트는 비동기 처리를 위한 하나의 패턴으로 콜백 함수를 사용한다.
- ES6에서 비동기 처리를 위한 또 다른 패턴으로 프로미스를 도입했다.

## 45.1 비동기 처리를 위한 콜백 패턴의 단점

### 45.1.1 콜백 헬

```jsx
// get은 비동기 함수
// 비동기 함수는 함수 내부에 비동기로 동작하는 코드를 포함한 함수
const get = url => {
  const xhr = new XMLHttpRequest()
  xhr.open('GET', url)
  xhr.send()

  // onload 이벤트 핸들러는 비동기로 동작
  xhr.onload = () => {
    if (xhr.status === 200) {
      console.log(JOSN.parse(xhr.response))
    } else {
      console.log(`${xhr.status} ${xhr.statusText}`)
    }
  }
}

get('https://jsonplaceholder.typicode.com/posts/1')
```

- 비동기 함수를 호출하면 함수 내부의 비동기로 동작하는 코드가 완료되지 않았다 해도 기다리지 않고 즉시 종료된다. 즉, 비동기 함수 내부의 비동기로 동작하는 코드는 비동기 함수가 종료된 이후에 완료된다.
- `get` 함수를 호출하면 GET 요청을 전송하고 `onload` 이벤트 핸들러를 등록한 다음 `undefined`를 반환하고 즉시 종료된다. 즉, 비동기 함수인 get 함수 내부의 onload 이벤트 핸들러는 get 함수가 종료된 이후에 실행된다.
- 따라서 `get` 함수의 `onload` 이벤트 핸들러에서 서버의 응답 결과를 반환하거나 상위 스코프의 변수에 할당하면 기대한 대로 동작하지 않는다. 서버의 응답 결과를 반환하도록 수정해 보자.

```jsx
const get = url => {
  const xhr = new XMLHttpRequest()
  xhr.open('GET', url)
  xhr.send()

  xhr.onload = () => {
    if (xhr.status === 200) {
      return JOSN.parse(xhr.response)
    }
    console.error(`${xhr.status} ${xhr.statusText}`)
  }
}

const response = get('https://jsonplaceholder.typicode.com/posts/1')
console.log(response) // undefiend
```

- `get` 함수가 호출되면,
  1. `XMLHttpRequest` 객체를 생성
  2. HTTP 요청을 초기화
  3. HTTP 요청을 전송
  4. `xhr.onload` 이벤트 핸들러 프로퍼티에 이벤트 핸들러를 바인딩
  5. 종료
- `xhr.onload` 이벤트 핸들러 프로퍼티에 바인딩한 이벤트 핸들러의 반환문은 `get` 함수의 반환문이 아니다.

```jsx
let todos

const get = url => {
  const xhr = new XMLHttpRequest()
  xhr.open('GET', url)
  xhr.send()

  xhr.onload = () => {
    if (xhr.status === 200) {
      todos = JOSN.parse(xhr.response)
    }
    console.error(`${xhr.status} ${xhr.statusText}`)
  }
}

const response = get('https://jsonplaceholder.typicode.com/posts/1')
console.log(response) // undefiend
```

- `xhr.onload` 이벤트 핸들러에서 서버의 응답을 상위 스코프의 변수에 할당하면 처리 순서가 보장되지 안는다.
  - `xhr.onload` 이벤트 핸들러는 즉시 실행되는 것이 아니라, load 이벤트가 발생하면 태스크 큐에 저장되어 대기하다가 콜 스택이 비면 이벤트 루프에 의해 콜 스택으로 푸시되어 실행된다.
  - `xhr.onload` 이벤트 핸들러가 실행되는 시점에는 콜 스택이 빈 상태여야 하므로 `console.log`는 이미 종료된 이후다.
- 비동기 함수는 비동기 처리 결과를 외부에 반환할 수 없고, 상위 스코프 변수에 할당할 수도 없다.
- 비동기 함수 처리 결과에 대한 후속 처리는 비동기 함수 내부에서 수행해야 한다.

```jsx
const get = (url, successCallback, failureCallback) => {
  const xhr = new XMLHttpRequest()
  xhr.open('GET', url)
  xhr.send()

  xhr.onload = () => {
    if (xhr.status === 200) {
      successCallback(JOSN.parse(xhr.response))
    } else {
      failureCallback(xhr.status)
    }
  }
}

get('https://jsonplaceholder.typicode.com/posts/1', console.log, console.error)
```

- 콜백 함수를 통해 비동기 처리 결과에 대한 후속 처리를 수행하는 비동기 함수가 비동기 처리 결과를 가지고 또다시 비동기 함수를 호출해야 한다면 콜백 함수 호출이 중첩되어 복잡도가 높아지는 현상이 발생하는데, 이를 콜백 헬이라 한다.

### 45.1.2 에러 처리의 한계

- 비동기 처리를 위한 콜백 패턴의 문제점 중에서 가장 심각한 것은 에러 처리가 곤란하다는 것이다.

```jsx
try {
  setTimeout(() => {
    throw new Error('Error!')
  }, 1000)
} catch (e) {
  console.error('캐치한 에러', e)
}
```

- try 코드 블록 내에서 호출한 setTimeout 함수는 1초 후에 콜백 함수가 실행되도록 타이머를 설정하고, 이후 콜백 함수는 에러를 발생시킨다. 하지만 이 에러는 catch 코드 블록에서 캐치되지 않는다.
  1. 비동기 함수인 setTimeout이 호출
  2. setTimeout 함수의 실행 컨텍스트가 생성되어 콜 스택에 푸시되어 실행
  3. setTimeout은 비동기 함수이므로 콜백 함수가 호출되는 것을 기다리지 않고 즉시 종료되어 콜 스택에서 제거
  4. 이후 타이머가 만료되면 setTimeout 함수의 콜백 함수는 태스크 큐로 푸시되고 콜 스택이 비어졌을 때 이벤트 루프에 의해 콜 스택으로 푸시되어 실행
- setTimeout 함수의 콜백 함수가 실행될 때, setTimeout 함수는 이미 콜 스택에서 제거된 상태다. 이것은 setTimeout 함수의 콜백 함수를 호출한 것이 setTimeout 함수가 아니라는 것을 의미한다.
- setTimeout 함수의 콜백 함수의 호출자가 setTimeout 함수라면 콜 스택의 현재 실행 중인 실행 컨텍스트가 콜백 함수의 실행 컨텍스트일 때 현재 실행 중인 실행 컨텍스트의 하위 실행 컨텍스트가 setTimeout 함수여야 한다.
- 에러는 호출자 방향으로 전파된다. 즉, 콜 스택의 아래 방향으로 전파된다. 하지만 앞서 살펴본 바와 같이 setTimeout 함수의 콜백 함수를 호출한 것은 setTimeout 함수가 아니다. 따라서 setTimeout 함수의 콜백 함수가 발생시킨 에러는 catch 블록에서 캐치되지 않는다.

## 45.2 프로미스의 생성

- Promise 생성자 함수는 비동기 처리를 수행할 콜백 함수를 인수로 전달받는데 이 콜백 함수(executor)는 resolve와 reject 함수를 인수로 전달받는다.

```jsx
const promise = new Promise((resolve, reject) => {
	if (/* 비동기 처리 성공 */) {
		resolve('result')
	} else {
		reject('failure reason')
	}
})
```

```jsx
const promiseGet = url => {
  return new Promise((resolve, reject) => {
    const xhr = new XMLHttpRequest()
    xhr.open('GET', url)
    xhr.send()

    xhr.onload = () => {
      if (xhr.status === 200) {
        resolve(JOSN.parse(xhr.response))
      } else {
        reject(new Error(xhr.status))
      }
    }
  })
}

promiseGet('https://jsonplaceholder.typicode.com/posts/1')
```

- 비동기 함수인 promiseGet은 함수 내부에서 프로미스를 생성하고 반환한다.
- 비동기 처리는 Promise 생성자 함수가 인수로 전달받은 콜백 함수 내부에서 수행한다.
  - 비동기 처리가 성공하면 비동기 처리 결과를 resolve 함수에 인수로 전달하면서 호출
  - 비동기 처리가 실패하면 에러를 reject 함수에 인수로 전달하면서 호출
- 프로미스는 다음과 같이 현재 비동기 처리가 어떻게 진행되고 있는지를 나타내는 상태 정보를 갖는다.
  - 웹 브라우저의 JavaScript 엔진 또는 Node.js에서 실행되는 JavaScript 엔진은 해당 상태를 메모리에 저장하고 관리한다.
    | 프로미스의 상태 정보 | 의미 | 상태 변경 조건 |
    | -------------------- | ------------------------------------- | -------------------------------- |
    | pending | 비동기 처리가 아직 수행되지 않은 상태 | 프로미스가 생성된 직후 기본 상태 |
    | fulfilled | 비동기 처리가 수행된 상태 (성공) | resolve 함수 호출 |
    | rejected | 비동기 처리가 수행된 상태 (실패) | reject 함수 호출 |
- 프로미스 상태는 resolve 또는 reject 함수를 호출하는 것으로 결정된다.
  - 비동기 처리 성공: resolve 함수를 호출해 프로미스를 fulfilled 상태로 변경한다.
  - 비동기 처리 실패: reject 함수를 호출해 프로미스를 rejected 상태로 변경한다.
- fulfilled 또는 rejected 상태를 settled 상태라고 한다. settled 상태는 fulfilled 또는 rejected 상태와 상관없이 pending이 아닌 상태로 비동기 처리가 수행된 상태를 말한다.
  - settled 상태가 되면 더는 다른 상태로 변화할 수 없다.

```jsx
const fulfilled = new Promise(resolve => resolve(1))
```

<img width="627" alt="image" src="https://user-images.githubusercontent.com/88878874/272922332-4b6ef15a-6b5a-4319-b90c-80f713294a62.png">

- 비동기 처리가 성공하면 프로미스는 pending 상태에서 fulfilled 상태로 변화한다. 그리고 비동기 처리 결과인 1을 값으로 갖는다.
- **`Promise`**가 성공적으로 완료될 때 전달되는 값을 얻는 방법

```jsx
fulfilled.then(value => {
  console.log(value) // 1
})
```

## 45.3 프로미스의 후속 처리 메서드

- 프로미스의 비동기 처리 상태가 변화하면 이에 따른 후속 처리를 해야 한다.
- then, catch, finally를 제공한다.
- 프로미스의 비동기 처리 상태가 변화하면 후속 처리 메서드에 인수로 전달한 콜백 함수가 선택적으로 호출된다.

  - 이때 후속 처리 메서드의 콜백 함수에 프로미스의 `처리 결과`가 인수로 전달된다.

  ```jsx
  const promise = new Promise((resolve, reject) => {
    resolve('성공!')
  })

  promise.then(result => {
    console.log(result) // 성공! -> 처리 결과
  })
  ```

### 45.3.1 Promise.prototype.then

- then 메서드는 두 개의 콜백 함수를 인수로 전달받는다.
  1. 첫 번째 콜백 함수는 프로미스가 fulfilled 상태가 되면 호출된다. 이때 콜백 함수는 프로미스의 비동기 처리 결과를 인수로 전달받는다.
  2. 두 번째 콜백 함수는 프로미스가 rejected 상태가 되면 호출된다. 이때 콜백 함수는 프로미스의 에러를 인수로 전달받는다.
- then 메서드는 언제나 프로미스를 반환한다.
  - 만약 then 메서드의 콜백 함수가 프로미스를 반환하면 그 프로미스를 그대로 반환하고, 콜백 함수가 프로미스가 아닌 값을 반환하면 그 값을 암묵적으로 resolve 또는 reject하여 프로미스를 생성해 반환한다.

### 45.3.2 Promise.prototype.catch

- catch 메서드는 한 개의 콜백 함수를 인수로 전달받는다.
- catch 메서드의 콜백 함수는 프로미스가 rejected 상태인 경우에만 호출된다.

```jsx
new Promise((_, reject) => reject(new Error('reject'))).catch(e =>
  console.log(e)
)
```

### 45.3.3 Promise.prototype.finally

- finally 메서드는 한 개의 콜백 함수를 인수로 전달받는다.
- finally 메서드의 콜백 함수는 프로미스의 성공 또는 실패와 상관없이 무조건 한 번 호출된다.
- finally 메서드도 언제나 프로미스를 반환한다.
- 프로미스로 구현한 비동기 함수 get을 사용해 후속 처리 구현해보자.

  ```jsx
  const promiseGet = url => {
  	return new Promise((resolve, reject) => {
  		const xhr = new XHLHttpRequest()
  		xhr.open('GET', url)
  		xhr.send()

  		xhr.onload = () => {
  			if (xhr.status === 200) {
  				resolve(JSON.parse(xhr.response)
  			} else {
  				reject(new Error(xhr.status))
  			}
  		}
  	})
  }

  promiseGet('https://jsonplaceholder.typicode.com/posts/1')
  	.then(res => console.log(res))
  	.catch(err => console.log(err))
  	.finally(() => console.log('Bye!')
  ```

## 45.4 프로미스의 에러 처리

- 비동기 처리에서 발생한 에러는 then 메서드의 두 번째 콜백 함수로 처리할 수 있다.

```jsx
const wrongUrl = 'https://jsonplaceholder.typicode.com/xxx/1'

promiseGet(wrongUrl).then(
  res => console.log(res),
  err => console.log(err)
)
// Error: 404
```

- then 메서드의 두 번째 콜백 함수는 첫 번째 콜백 함수에서 발생한 에러를 캐치하지 못하고 코드가 복잡해져서 가독성이 좋지 않다.

```jsx
const wrongUrl = 'https://jsonplaceholder.typicode.com/xxx/1'

promiseGet('https://jsonplaceholder.typicode.com/posts/1')
  .then(res => console.log(res))
  .catch(err => console.log(err)) // Error: 404
```

- catch 메서드를 모든 then 메서드를 호출한 이후에 호출하면 비동기 처리에서 발생한 에러 뿐만 아니라 then 메서드 내부에서 발생한 에러까지 모두 캐치할 수 있다.

### 45.5 프로미스 체이닝

```jsx
const url = 'https://jsonplaceholder.typicode.com'

promiseGet(`${url}/posts/1`)
  .then(({ userId }) => promiseGet(`${url}/users/${userId}`)) // 1️⃣
  .then(userInfo => console.log(userInfo)) // 2️⃣
  .catch(err => console.log(err)) // 3️⃣
```

- then, catch, finally 후속 처리 메서드는 언제나 프로미스를 반환하므로 연속적으로 호출할 수 있다.
  - 이를 프로미스 체이닝이라 한다.

| 후속 처리 메서드 | 콜백 함수의 인수                                                                        | 후속 처리 메서드의 반환값                  |
| ---------------- | --------------------------------------------------------------------------------------- | ------------------------------------------ |
| 1️⃣ then          | promiseGet 함수가 반환한 프로미스가 resolve한 값 (id가 1인 post)                        | 콜백 함수가 반환한 프로미스                |
| 2️⃣ then          | 첫 번째 then 메서드가 반환한 프로미스가 resolve한 값 (post의 userId로 취득한 user 정보) | 콜백 함수가 반환한 값을 resolve한 프로미스 |
| 3️⃣ catch         | promiseGet 함수 또는 앞선 후속 처리 메서드가 반환한 프로미스가 reject한 값              | 콜백 함수가 반환한 값을 resolve한 프로미스 |

- 콜백 패턴은 가독성이 좋지 않아 ES8에 도입된 async/await를 통해 해결할 수 있다.

```jsx
const url = 'https://jsonplaceholder.typicode.com'(async () => {
  const { userId } = await promiseGet(`${url}/posts/1`)
  const userInfo = await promiseGet(`${url}/users/${userId}`)

  console.log(userInfo)
})()
```

## 45.6 프로미스의 정적 메서드

- Promise는 주로 생성자 함수로 사용되지만 함수도 객체이므로 메서드를 가질 수 있다.
- 5가지의 정적 메서드를 제공한다.

### 45.6.1 Promise.resolve / Promise.reject

- Promise.resolve와 Promise.reject 메서드는 이미 존재하는 값을 래핑하여 프로미스를 생성하기 위해 사용한다.

```jsx
const resolvePromise = Promise.resolve([1, 2, 3])
resolvedPromise.then(console.log) // [1, 2, 3]

const resolvePromise = new Promise(resolve => resolve([1, 2, 3]))
resolvedPromise.then(console.log) // [1, 2, 3]
```

```jsx
const rejectedPromise = Promise.reject(new Error('Error!'))
rejectedPromise.catch(console.log) // Error: Error!

const rejectedPromise = new Promise((_, reject) => reject(new Error('Error!')))
rejectedPromise.catch(console.log) // Error: Error!
```

### 45.6.2 Promise.all

- 여러 개의 비동기 처리를 모두 병렬 처리할 때 사용한다.

```jsx
const requestData1 = () =>
  new Promise(resolve => setTimeout(() => resolve(1), 3000))
const requestData2 = () =>
  new Promise(resolve => setTimeout(() => resolve(2), 2000))
const requestData3 = () =>
  new Promise(resolve => setTimeout(() => resolve(3), 1000))

// then 메서드 사용
const res = []
requestData1()
  .then(data => {
    res.push(data)
    return requestData2()
  })
  .then(data => {
    res.push(data)
    return requestData3()
  })
  .then(data => {
    res.push(data)
    console.log(res) // [1, 2, 3]
  })
  .catch(console.error)

// Promise.all 사용
Promise.all(requestData1(), requestData2(), requestData3())
  .then(console.log) // [1, 2, 3]
  .catch(console.error)
```

- Promise.all 메서드는 프로미스를 요소로 갖는 배열 등의 이터러블을 인수로 전달받는다.
- Promise.all 메서드는 인수로 전달받은 배열의 모든 프로미스가 모두 fulfilled 상태가 되면 종료한다.
- 모든 프로미스가 fulfilled 상태가 되면 resolve된 처리 결과를 모두 배열에 저장해 새로운 프로미스를 반환한다.
  - 프로미스가 얼마나 빠르게 완료되는지와 상관없이, 반환된 결과 배열은 원래의 프로미스 배열의 순서를 유지한다.
- Promise.all 메서드는 인수로 전달받은 배열의 프로미스가 하나라도 rejected 상태가 되면 나머지 프로미스가 fulfilled 상태가 되는 것을 기다리지 않고 즉시 종료한다.

```jsx
Promise.all([
  new Promise((_, reject) =>
    setTimeout(() => reject(new Error('Error 1')), 3000)
  ),
  new Promise((_, reject) =>
    setTimeout(() => reject(new Error('Error 2')), 2000)
  ),
  new Promise((_, reject) =>
    setTimeout(() => reject(new Error('Error 3')), 1000)
  )
])
  .then(console.log)
  .catch(console.log) // Error: Error 3
```

- 위 예제의 경우 세 번째 프로미스가 가장 먼저 rejected 상태가 되므로 세 번째 프로미스가 reject한 에러가 catch 메서드로 전달된다.
- Promise.all 메서드는 인수로 전달받은 이터러블의 요소가 프로미스가 아닌 경우 Promise.resolve 메서드를 통해 프로미스로 래핑한다.

```jsx
Promise.all([
  1, // Promise.resolve(1)
  2, // Promise.resolve(2)
  3 // Promise.resolve(3)
])
  .then(console.log) // [1, 2, 3]
  .catch(console.log)
```

### 45.6.3 Promise.race

- 프로미스를 요소로 갖는 배열 등의 이터러블을 인수로 전달받는다.
- 가장 먼저 fulfilled 상태가 된 프로미스의 처리 결과를 resolve하는 새로운 프로미스를 반환한다.

```jsx
Promise.race([
  new Promise(resolve => setTimeout(() => resolve(1), 3000)), // 1
  new Promise(resolve => setTimeout(() => resolve(2), 2000)), // 2
  new Promise(resolve => setTimeout(() => resolve(3), 1000)) // 3
])
  .then(console.log) // 3
  .catch(console.log)
```

- rejected 상태가 되면 Promise.all 멤서드와 동일하게 처리된다.

### 45.6.4 Promise.allSettled

- 프로미스를 요소로 갖는 배열 등의 이터러블을 인수로 전달받는다.
- 전달받은 프로미스가 모두 settled 상태가 되면 처리 결과를 배열로 반환한다.

```jsx
Promise.allSettled([
	new Promise(resolve => setTimeout(() => resolve(1), 2000))
	new Promise((_, reject) => setTimeout(() => reject(new Error('Error!')), 1000))
]).then(console.log)

/*
[
	{status: "fulfilled", value: 1}
	{status: "rejected", reason: Error: Error! at <anonymous>:3:54}
]
*/
```

## 45.7 마이크로태스크 큐

```jsx
setTimeout(() => console.log(1), 0)

Promise.resolve()
  .then(() => console.log(2))
  .then(() => console.log(3))
```

- 2 → 3 → 1의 순서로 출력된다.
- 프로미스의 후속 처리 메서드의 콜백 함수는 태스크 큐가 아니라 마이크로태스크 큐에 저장되기 때문이다.
- 마이크로태스크 큐에는 프로미스의 후속 처리 메서드의 콜백 함수가 일시 저장된다.
  - 그 외의 비동기 함수의 콜백 함수나 이벤트 핸들러는 태스크 큐에 일시 저장된다.
- 마이크로태스크 큐는 태스트 큐보다 우선순위가 높다.

## 45.8 fetch

- fetch 함수는 XMLHttpRequest 객체와 마찬가지로 HTTP 요청 전송 기능을 제공하는 클라이언트 사이드 Web API다.
- fetch 함수는 HTTP 요청을 전송할 URL과 HTTP 요청 메서드, HTTP 요청 헤더, 페이로드 등을 설정한 객체를 전달한다.
  ```jsx
  const promise = fetch(url [, options])
  ```
- fetch 함수는 HTTP 응답을 나타내는 Response 객체를 래핑한 Promise 객체를 반환한다.

```jsx
fetch('https://jsonplaceholder.typicode.com/todos/1').then(response =>
  console.log(response)
)
```

<img width="633" alt="image" src="https://user-images.githubusercontent.com/88878874/272922126-87b6a1ef-c2ec-4652-bf3b-12f98a635cc8.png">

- Response.prototype에는 Response 객체에 포함되어 있는 HTTP 응답 몸체를 위한 다양한 메서드를 제공한다.
- fetch 함수가 반환한 프로미스가 래핑하고 있는 MINE 타입이 application/json인 HTTP 응답 몸체를 취득하려면 Response.prototype.json 메서드를 사용한다.

```jsx
const wrongUrl = 'https://jsonplaceholder.typicode.com/XXX/1'

fetch(wrongUrl)
  .then(() => console.log('ok'))
  .catch(() => console.log('error'))
```

- 부적절한 URL이 지정되었기 때문에 404 에러가 발생하고 catch 후속 처리 메서드에 의해 ‘error’가 출력될 것처럼 보이지만 ‘ok’가 출력된다.
- fetch 함수가 반환하는 프로미스는 기본적으로 404, 500 같은 에러가 발생해도 에러를 reject하지 않고 불리언 타입의 ok 상태를 false로 설정한 response 객체를 resolve한다.
- 오프라인 등의 네트워크 장애나 CORS 에러에 의해 요청이 완료되지 못한 경우에만 프로미스를 reject한다.
- fetch 함수를 사용할 때는 다음과 같이 ok 상태를 확인해 명시적으로 에러를 처리할 필요가 있다.

  ```jsx
  const wrongUrl = 'https://jsonplaceholder.typicode.com/XXX/1'

  fetch(wrongUrl)
    .then(response => {
      if (!response.ok) throw new Error(response.statusText)
      return response.json()
    })
    .then(todo => console.log(todo))
    .catch(err => console.error(err))
  ```

- axios는 모든 HTTP 에러를 reject하는 프로미스를 반환한다. 따라서 모든 에러를 catch에서 처리할 수 있어 편리하다.

### fetch 함수를 통해 HTTP 요청 전송

```jsx
const request = {
	get(url) {
		return fetch(url)
	},
	post(url, payload) {
		return fetch(url, {
			method: 'POST',
			headers: { 'content-Type': 'application/json' },
			body: JSON.stringify(payload)
		})
	},
	patch(url, payload) {
		return fetch(url, {
			method: 'PATCH',
			headers: { 'content-Type': 'application/json' },
			body: JSON.stringify(payload)
		})
	},
	delete(url) {
		return fetch(url, { method: 'DELETE' }
	}
}
```

### 1. GET 요청

```jsx
request
  .get('https://jsonplaceholder.typicode.com/todos/1')
  .then(response => {
    if (!response.ok) throw new Error(response.statusText)
    return response.json()
  })
  .then(todos => console.log(todos))
  .catch(err => console.log(err))
```

### 2. POST 요청

```jsx
request
  .post('https://jsonplaceholder.typicode.com/todos/1', {
    userId: 1,
    title: 'JavaScript',
    completed: false
  })
  .then(response => {
    if (!response.ok) throw new Error(response.statusText)
    return response.json()
  })
  .then(todos => console.log(todos))
  .catch(err => console.log(err))
```

### 3. PATCH 요청

```jsx
request
  .patch('https://jsonplaceholder.typicode.com/todos/1', {
    completed: true
  })
  .then(response => {
    if (!response.ok) throw new Error(response.statusText)
    return response.json()
  })
  .then(todos => console.log(todos))
  .catch(err => console.log(err))
```

### 4. DELETE 요청

```jsx
request
  .delete('https://jsonplaceholder.typicode.com/todos/1')
  .then(response => {
    if (!response.ok) throw new Error(response.statusText)
    return response.json()
  })
  .then(todos => console.log(todos))
  .catch(err => console.log(err))
```