### 1. try … catch … finally 문

기본적으로 체러 처리를 구현하는 방법은 크게 두 가지가 있다.

- querySelector나 Array#find메서드처럼 예외적인 상황이 발생하면 반환하는 값을 if 문이나 단축 평가 또는 옵셔널 체이닝 연산자를 통해 확인해서 처리하는 방법
- 에러 처리 코드를 미리 등록해 두고 에러 발생 시 에러 처리 코드로 점프하는 방법

`try … catch … finally`문은 두 번째 방법이다


```jsx
console.log('[Start]');

try {
    // 실행할 코드(에러가 발생할 가능성이 있는 코드)
    foo();
} catch (err) {
    // try 코드 블록에서 에러가 발생하면 이 코드 블록의 코드가 실행된다.
    // err에는 try 코드 블록에서 발생한 Error 객체가 전달된다.
    console.error(err); // ReferenceError: foo is not defined
} finally {
    // 에러 발생과 상관없이 반드시 한 번 실행된다.
    console.log('finally');
}

// try...catch...finally 문으로 에러를 처리하면 프로그램이 강제 종료되지 않는다.
console.log('[End]');
```

finally문은 불필요하다면 생략 가능하다.

`try … catch … finally`문으로 에러를 처리하면 프로그램이 강제 종료되지 않는다.


### 2. Error 객체

Error생성자 함수는 에러 객체를 생성한다.

```jsx
const error = new Error('invalid');
```

### 3. throw문

Error생성자 함수로 에러 객체를 생성한다고 에러가 발생하는 것은 아니다. 에러 객체 생성과 발생은 의미가 다르다.

에러를 발생시키려면 `try`코드 블록에서 `throw`문으로 에러 객체를 던저야 한다.

에러를 던지면 catch 문의 에러 변수가 생성되고 던져진 에러 객체가 할당된다. 그리고 catch코드 블록이 실행된다.

```jsx
try {
    // 에러 객체를 던지면 catch 코드 블록이 실행되기 시작한다.
    throw new Error('something wrong');
} catch (error) {
    console.log(error);
}
```



