# 47. 에러 처리

## 47.1 에러 처리의 필요성

에러가 발생하지 않는 코드를 작성하는 것은 불가능하다.

발생한 에러에 대해 대처하지 않고 방치하면 프로그램을 강제 종료된다.

```javascript
console.log("[Start]");

foo(); // ReferenceError: foo is not defined
// 발생한 에러를 방치하면 프로그램은 강제 종료된다.

// 에러에 의해 프로그램이 강제 종료되어 아래 코드는 실행되지 않는다.
console.log("[End]");
```

또한, 에러를 발생시키지 않고 null을 반환하는 등의 경우도 있기에

개발한 내용 상으로 다르게 표현될 수 있어서 더 중요하다

## 47.2 try...catch...finally 문

null 이나 -1을 반환하는 값을 if문이나 옵셔널 체이닝(?.)을 통해서 처리하는 방법도 있지만 try...catch...finally로 에러 처리를 할 수 있다

```javascript
try {
  // 실행할 코드(에러가 발생할 가능성이 있는 코드)
} catch (err) {
  // try 코드 블록에서 에러가 발생하면 이 코드 블록의 코드가 실행된다
  // err에는 try 코드 블록에서 발생한 Error 객체가 전달된다.
} finally {
  // 에러 발생과 상관없이 반드시 한 번 실행된다.
}
```

```javascript
console.log("[Start]");

try {
  // 실행할 코드(에러가 발생할 가능성이 있는 코드)
  foo();
} catch (err) {
  // try 코드 블록에서 에러가 발생하면 이 코드 블록의 코드가 실행된다.
  // err에는 try 코드 블록에서 발생한 Error 객체가 전달된다.
  console.error(err); // ReferenceError: foo is not defined
} finally {
  // 에러 발생과 상관없이 반드시 한 번 실행된다.
  console.log("finally");
}

// try...catch...finally 문으로 에러를 처리하면 프로그램이 강제 종료되지 않는다.
console.log("[End]");
```

## 47.3 Error 객체

```javascript
const error = new Error("invalid");
```

Error 생ㅅ어자 함수가 생성한 에러 객체는 `message` 프로퍼티와 `stack` 프로퍼티를 가진다.

stack 프로퍼티의 값은 에러를 발생시킨 `콜 스택의 호출 정보`를 나타내는 문자열이며 디버깅 목적으로 사용한다

에러 객체의 프로토타입은 모두 Error.prototype을 상속받는다

```javascript
1 @ 1;    // SyntaxError: Invalid or unexpected token
foo();    // ReferenceError: foo is not defined
null.foo; // TypeError: Cannot read property 'foo' of null
new Array(-1); // RangeError: Invalid array length
decodeURIComponent('%'); // URIError: URI malformed
```

## 47.4 throw 문

에러 객체를 생성한다고 에러가 발생하는 것은 아니다

에러를 발생시키기 위해서는 throw문으로 에러 객체를 던져야한다

```javascript
try {
  // 에러 객체를 생성한다고 에러가 발생하는 것은 아니다.
  new Error("something wrong");
} catch (error) {
  console.log(error);
}
```

> throw 표현식

```javascript
try {
  // 에러 객체를 던지면 catch 코드 블록이 실행되기 시작한다.
  throw new Error("something wrong");
} catch (error) {
  console.log(error);
}
```

## 47.5 에러의 전파

```javascript
const foo = () => {
  throw Error("foo에서 발생한 에러"); // ④
};

const bar = () => {
  foo(); // ③
};

const baz = () => {
  bar(); // ②
};

try {
  baz(); // ①
} catch (err) {
  console.error(err);
}
```

throw된 에러를 캐치하지 않으면 `호출자 방향`으로 전파된다.

# 892p 이미지

setTimeout이나 프로미스 후속 처리 메서드의 콜백 함수는 `함소 호출자가 없기`때문에 처리를 잘해야한다.
