# 46장-제너레이터와\_async_await

제너레이터란?

제너레이터는 실행을 일시 중지했다가 재개할 수 있는 특수한 함수이다. 일반 함수와 달리 제너레이터는 호출자에게 실행 제어권을 양도할 수 있으며, 호출자와 양방향으로 상태를 주고받을 수 있다. 또한, 호출 시 제너레이터 객체를 반환하는데, 이 객체는 이터러블이면서 이터레이터이다.

## 제너레이터 함수 정의

제너레이터 함수는 `function*` 키워드로 선언하며, 하나 이상의 `yield` 표현식을 포함한다. 제너레이터 함수는 화살표 함수로 정의할 수 없으며, 생성자 함수로 사용할 수 없다.

```js
function* genFunc() {
  yield 1;
}
```

## 제너레이터 객체

제너레이터 함수 호출 시 함수는 실행되지 않고 제너레이터 객체가 반환된다. 이 객체는 이터러블과 이터레이터를 동시에 갖추며, `next`, `return`, `throw` 메서드를 가진다.

- `next()` : `yield` 된 값을 반환하며, 실행을 일시 중지한다.
- `return()` : 값을 반환하며 제너레이터를 종료한다.
- `throw()` : 에러를 발생시키고 종료한다.

```js
function* genFunc() {
  yield 1;
  yield 2;
  yield 3;
}

const generator = genFunc();
console.log(generator.next()); // {value: 1, done: false}
console.log(generator.next()); // {value: 2, done: false}
console.log(generator.next()); // {value: 3, done: false}
console.log(generator.next()); // {value: undefined, done: true}
```

## 제너레이터 활용

### 1. 이터러블 구현

제너레이터 함수로 간단히 이터러블을 구현할 수 있다.

```js
const infiniteFibonacci = (function* () {
  let [pre, cur] = [0, 1];
  while (true) {
    [pre, cur] = [cur, pre + cur];
    yield cur;
  }
})();

for (const num of infiniteFibonacci) {
  if (num > 10000) break;
  console.log(num);
}
```

### 2. 비동기 처리

제너레이터는 `yield`와 `next()`를 통해 비동기 처리를 동기적으로 구현할 수 있다.

```js
const async = (generatorFunc) => {
  const generator = generatorFunc();

  const onResolved = (arg) => {
    const result = generator.next(arg);
    return result.done
      ? result.value
      : result.value.then((res) => onResolved(res));
  };

  return onResolved;
};

async(function* fetchTodo() {
  const url = "https://jsonplaceholder.typicode.com/todos/1";
  const response = yield fetch(url);
  const todo = yield response.json();
  console.log(todo);
})();
```

## async/await

`async/await`는 제너레이터보다 간단하고 가독성이 좋은 방식으로 비동기 처리를 구현할 수 있다.

```js
async function fetchTodo() {
  const url = "https://jsonplaceholder.typicode.com/todos/1";
  const response = await fetch(url);
  const todo = await response.json();
  console.log(todo);
}
```

### 에러 처리

`async/await`에서 에러 처리는 `try...catch`문을 사용한다.

```js
const foo = async () => {
  try {
    const wrongUrl = "https://wrong.url";
    const response = await fetch(wrongUrl);
    const data = await response.json();
    console.log(data);
  } catch (err) {
    console.error(err); // TypeError: failed to fetch
  }
};

foo();
```
